Workbook

Sheet Dashboard
B2: Phone prospecting — construction projects (Infopro "DRINGEND" cards)
B3: 91 PDF files · 108 projects · 204 contacts. The figures below update automatically from the Calls sheet.
B5: Overview | F5: Contacts by status
B6: Projects | C6: =COUNTA(Projects!$A$2:$A$109) -> 108 | F6: Status | G6: Contacts
B7: Contacts to call | C7: =COUNTA(Calls!$E$2:$E$9999) -> 204 | F7: To call | G7: =COUNTIF(Calls!$O$2:$O$9999,F7) -> 194
B8: Contacts without a phone number | C8: =COUNTIF(Calls!$G$2:$G$9999,"To be found") -> 22 | F8: Call back | G8: =COUNTIF(Calls!$O$2:$O$9999,F8) -> 7
B9: Total works value | C9: =SUM(Projects!$K$2:$K$109) -> 78470000 | D9: duplicates included | F9: Follow-up by email | G9: =COUNTIF(Calls!$O$2:$O$9999,F9) -> 1
F10: Interested | G10: =COUNTIF(Calls!$O$2:$O$9999,F10) -> 0
B11: Call progress | F11: Meeting booked | G11: =COUNTIF(Calls!$O$2:$O$9999,F11) -> 0
B12: Contacts called (≥ 1 attempt) | C12: =COUNTIF(Calls!$P$2:$P$9999,">0") -> 10 | F12: Quote requested | G12: =COUNTIF(Calls!$O$2:$O$9999,F12) -> 0
B13: Coverage rate | C13: =IFERROR(C12/C7,0) -> 0.049019608 | F13: Not interested | G13: =COUNTIF(Calls!$O$2:$O$9999,F13) -> 0
B14: Total attempts | C14: =SUM(Calls!$P$2:$P$9999) -> 10 | F14: Already has a supplier | G14: =COUNTIF(Calls!$O$2:$O$9999,F14) -> 0
B15: Contacts reached | C15: =COUNTIF(Calls!$N$2:$N$9999,"Reached*") -> 5 | F15: Not a fit | G15: =COUNTIF(Calls!$O$2:$O$9999,F15) -> 0
B16: Reach rate | C16: =IFERROR(C15/C12,0) -> 0.5 | D16: reached / called | F16: Project completed / cancelled | G16: =COUNTIF(Calls!$O$2:$O$9999,F16) -> 0
B17: Interested + meetings + quotes | C17: =COUNTIF(Calls!$O$2:$O$9999,"Interested")+COUNTIF(Calls!$O$2:$O$9999,"Meeting booked")+COUNTIF(Calls!$O$2:$O$9999,"Quote requested") -> 0 | F17: Closed – no current need | G17: =COUNTIF(Calls!$O$2:$O$9999,F17) -> 2
B18: Conversion rate | C18: =IFERROR(C17/C15,0) -> 0 | D18: qualified / reached | F18: Total | G18: =SUM(G7:G17) -> 204
B19: Overdue follow-ups | C19: =SUMPRODUCT((Calls!$S$2:$S$9999<>"")*(Calls!$S$2:$S$9999<=TODAY())*((Calls!$O$2:$O$9999="Call back")+(Calls!$O$2:$O$9999="Follow-up by email")+(Calls!$O$2:$O$9999="Interested")+(Calls!$O$2:$O$9999="Quote requested")+(Calls!$O$2:$O$9999="To call"))) -> 0
F20: Contacts by priority
F21: Priority | G21: Contacts | H21: Still to call
F22: A | G22: =COUNTIF(Calls!$C$2:$C$9999,F22) -> 50 | H22: =COUNTIFS(Calls!$C$2:$C$9999,F22,Calls!$O$2:$O$9999,"To call") -> 46
F23: B | G23: =COUNTIF(Calls!$C$2:$C$9999,F23) -> 52 | H23: =COUNTIFS(Calls!$C$2:$C$9999,F23,Calls!$O$2:$O$9999,"To call") -> 50
F24: C | G24: =COUNTIF(Calls!$C$2:$C$9999,F24) -> 102 | H24: =COUNTIFS(Calls!$C$2:$C$9999,F24,Calls!$O$2:$O$9999,"To call") -> 98
F26: Projects by stage
F27: Stage | G27: Projects
F28: Permit application filed | G28: =COUNTIF(Projects!$H$2:$H$109,F28) -> 35
F29: Permit granted | G29: =COUNTIF(Projects!$H$2:$H$109,F29) -> 73
B32: Reminders
B33: 1. On the Calls sheet, filter Status = "To call" and sort by Priority.
B34: 2. Fill in the yellow columns straight after each call (result, status, date, follow-up).
B35: 3. Never leave a row open without a follow-up date: overdue follow-ups turn red.
B36: 4. "Linked projects" > 1: the same person handles several projects, so cover them in one call.
B37: 5. Open the PDF named in column A for the full project card.

Sheet How to use
B2: How to use this prospecting file
B4: Sheets
B5: Dashboard | C5: Automatically calculated indicators (progress, reach rate, conversion, overdue follow-ups).
B6: Calls | C6: The call list: one row per contact and per project. This is where you work.
B7: Projects | C7: One row per project (= one PDF page), with all the data extracted from the card.
B8: Lists | C8: Drop-down values and priority thresholds (editable).
B10: Colour code
B11: Dark teal header | C11: Data extracted from the PDFs (do not edit, except to correct).
B12: Orange header + yellow cells | C12: Columns to fill in while calling.
B13: Grey header | C13: Extra details: grouped columns, click the "−" above them to hide them.
B14: Green row | C14: Prospect interested, meeting booked or quote requested.
B15: Greyed-out row | C15: Closed (not interested, not a fit, already has a supplier, project completed).
B16: Red follow-up date | C16: Overdue follow-up on a row that is still open: deal with it first.
B17: "To be found" (orange) | C17: No number on the card: look it up on local.ch / search.ch / the company website.
B19: Columns to fill in
B20: Last call result | C20: What happened: reached (right person or gatekeeper), voicemail, no answer, busy, wrong number.
B21: Status | C21: Where the prospect stands: to call → call back → interested → meeting / quote; or closed.
B22: Attempts | C22: Add one per call (good practice: 5 to 6 attempts at most before closing).
B23: Last call date | C23: Date of the last call (Ctrl + ; inserts today's date).
B24: Next action / Follow-up date | C24: Always an action and a date, unless the row is closed.
B25: Notes | C25: Name and role of the person reached, stated need, objection, best time to call back.
B27: Example of a filled-in row
B28: Last call result | C28: Reached – gatekeeper / switchboard
B29: Status | C29: Call back
B30: Attempts | C30: 2
B31: Last call date | C31: 14/10/2026
B32: Next action | C32: Call back
B33: Follow-up date | C33: 16/10/2026
B34: Notes | C34: Switchboard: Mr Franco (facilities manager) on a site visit, call back Thursday after 2pm. 3rd-floor project confirmed.
B36: Glossary (cards are in German)
B37: Owner / client (Bauherr) | C37: The end client: the owner or tenant commissioning the works.
B38: Architect / planner | C38: The firm that designs the project and often specifies the suppliers.
B39: Permit application filed | C39: Baugesuch eingereicht: project awaiting approval, works still to come (earliest point to get in).
B40: Permit granted | C40: Baubewilligung erteilt: approval obtained, works starting soon (urgent).
B41: Infopro project ref. | C41: Objektnummer: unique project ID at Infopro Digital (Baublatt).
B43: Notes on the data
B44: Source | C44: Automatic extraction of the 91 PDFs in the "harworth" folder (Infopro Digital Schweiz cards).
B45: Original language | C45: Company names, addresses, project titles and descriptions are kept as they appear in the PDFs (mostly French).
B46: Multi-page files | C46: Some PDFs contain several projects: the "Page" column gives the project's page.
B47: Duplicates | C47: 3 projects appear in two different files ("Duplicate" column): call them only once.
...

Sheet Calls
A1: PDF file | B1: Page | C1: Priority | D1: Role | E1: Company | F1: Contact person | G1: Phone | H1: Email | I1: Project | J1: Site location | K1: Stage | L1: Works value (CHF) | M1: Linked projects (same contact) | N1: Last call result | O1: Status | P1: Attempts | Q1: Last call date | R1: Next action | S1: Follow-up date | T1: Notes / person reached | U1: Infopro project ref. | V1: Stage date | W1: Contact address | X1: Website | Y1: Site address | Z1: Category | AA1: Project description | AB1: Contact source | AC1: Duplicate
A2: DRINGEND 4.pdf | B2: 1 | C2: =IF(L2="","C",IF(L2>=Lists!$I$2,"A",IF(L2>=Lists!$I$3,"B","C"))) -> C | D2: Owner / client | E2: YNEO SA | F2: Nicky Suter | G2: 022 307 99 00 | H2: info@yneo.ch | I2: Aménagement d'un espace de coworking | J2: 1213 Petit-Lancy | K2: Permit granted | L2: 50000 | M2: =IF(G2="To be found",COUNTIF($E$2:$E$9999,E2),COUNTIF($G$2:$G$9999,G2)) -> 1 | N2: Reached – gatekeeper / switchboard | O2: Call back | P2: 1 | Q2: 46297 | R2: Call back | S2: 46300 | T2: Reception reached on 02/10/2026. Receptionist explained that Nicky Suter does not work on Fridays. Call back Monday afternoon and ask directly for Nicky Suter, Fit-out & Communications Manager. Secondary relevant contact: Melvin Bertagna, Site & Supplier Relations Manager. Chancy 59 appears to be already operational. The objective of the next call is therefore to qualify both this project and YNEO as a potential recurring Haworth account: current furniture supplier(s), whether suppliers are exclusive or selected project by project, upcoming fit-outs, new locations and refurbishment projects. YNEO operates several office locations in Geneva and ergonomic furniture is part of its client offering. Avoid referring to YNEO as a "coworking" operator during the call. Refer instead to their office locations / workspaces. | U2: 3417573 | V2: 46029 | W2: Route de Florissant 2, 1206 Genève | X2: http://www.yneo.ch | Y2: Route de Chancy 59, 1213 Petit-Lancy | Z2: Commerce and administration | AA2: Aménagement d'un espace de coworking au 3ème étage. | AB2: Detail card
A3: DRINGEND 4.pdf | B3: 1 | C3: =IF(L3="","C",IF(L3>=Lists!$I$2,"A",IF(L3>=Lists!$I$3,"B","C"))) -> C | D3: Architect / planner | E3: Marques | G3: To be found | I3: Aménagement d'un espace de coworking | J3: 1213 Petit-Lancy | K3: Permit granted | L3: 50000 | M3: =IF(G3="To be found",COUNTIF($E$2:$E$9999,E3),COUNTIF($G$2:$G$9999,G3)) -> 3 | O3: To call | P3: 0 | R3: Qualify through owner | S3: 46300 | T3: Do not call yet. "Marques" could not be reliably identified as the architect/planner for project reference 3417573 / Chancy 59 from the available information. Qualify this contact during the callback to Nicky Suter at YNEO on 05/10/2026. Ask whether fit-out, furniture specification and design are handled internally by YNEO or with an external architect/planner. If external, obtain: - exact company name - contact person - role - phone/email if available Same project as the YNEO SA Owner / client row. | U3: 3417573 | V3: 46029 | W3: 1205 Genève | Y3: Route de Chancy 59, 1213 Petit-Lancy | Z3: Commerce and administration | AA3: Aménagement d'un espace de coworking au 3ème étage. | AB3: Detail card
A4: DRINGEND 5.pdf | B4: 1 | C4: =IF(L4="","C",IF(L4>=Lists!$I$2,"A",IF(L4>=Lists!$I$3,"B","C"))) -> C | D4: Owner / client | E4: Yara Clean Ammonia Switzerland SA | F4: Ms Marie Demaison | G4: To be found | I4: Aménagement de bureau | J4: 1206 Genève | K4: Permit granted | L4: 40000 | M4: =IF(G4="To be found",COUNTIF($E$2:$E$9999,E4),COUNTIF($G$2:$G$9999,G4)) -> 1 | N4: Reached – project completed / no opportunity | O4: Closed – no current need | P4: 1 | Q4: 46297 | R4: None | T4: Project is completed. The works were related to an office relocation. Yara did not purchase new furniture as part of the move. The contact confirmed that there are currently no other office fit-out, refurbishment or furniture projects planned and therefore no current need for Haworth. No follow-up required unless a new project is identified in the future. | U4: 3416972 | V4: 46014 | W4: Route de Florissant 13, 1206 Genève | Y4: Route de Florissant 13, 1206 Genève | Z4: Commerce and administration | AA4: Aménagement de bureau au 7ème étage. | AB4: Detail card
A5: DRINGEND 5.pdf | B5: 1 | C5: =IF(L5="","C",IF(L5>=Lists!$I$2,"A",IF(L5>=Lists!$I$3,"B","C"))) -> C | D5: Architect / planner | E5: TJCA SA | F5: Ms Sabrina Harri | G5: 022 869 88 44 | H5: admin@tjca.ch | I5: Aménagement de bureau | J5: 1206 Genève | K5: Permit granted | L5: 40000 | M5: =IF(G5="To be found",COUNTIF($E$2:$E$9999,E5),COUNTIF($G$2:$G$9999,G5)) -> 4 | N5: Not reachable | O5: Call back | P5: 1 | Q5: 46297 | R5: Call back | S5: 46300 | T5: Attempted to reach Sabrina Harri regarding project reference 3416972 and TJCA's office fit-out / furniture specification activities. Not reachable. Call back on Monday 05/10/2026. The Yara project itself is already completed, so the objective of the next call is not to reopen that project. The objective is to qualify TJCA as a potential recurring architect / furniture prescriber for other office projects and identify any current projects where furniture specification is still open. Direct line identified for Sabrina Harri: 022 869 88 27. Email identified: sabrina.harri@tjca.ch | U5: 3416972 | V5: 46014 | W5: Chemin de la Bessonnette 7, 1224 Chêne-Bougeries | X5: http://www.tjca.ch | Y5: Route de Florissant 13, 1206 Genève | Z5: Commerce and administration | AA5: Aménagement de bureau au 7ème étage. | AB5: Detail card
A6: DRINGEND 6.pdf | B6: 1 | C6: =IF(L6="","C",IF(L6>=Lists!$I$2,"A",IF(L6>=Lists!$I$3,"B","C"))) -> B | D6: Owner / client | E6: von Rundstedt & Partner Suisse SA, succursale de Genève | F6: Ms Anne Donou | G6: 058 332 26 00 | H6: geneve@rundstedt.ch | I6: Transformation et rénovation de bureaux | J6: 1202 Genève | K6: Permit granted | L6: 150000 | M6: =IF(G6="To be found",COUNTIF($E$2:$E$9999,E6),COUNTIF($G$2:$G$9999,G6)) -> 1 | N6: Reached – project completed / no current opportunity | O6: Closed – no current need | P6: 1 | Q6: 46297 | R6: None | T6: Contact confirmed that the company has already completed its move. There are currently no additional office relocation, refurbishment, fit-out or furniture projects planned. No current opportunity for Haworth. No follow-up required unless a new project is identified in the future. | U6: 3416925 | V6: 46013 | W6: Boulevard Georges-Favon 18, 1204 Genève | X6: http://www.rundstedt.ch | Y6: Rue de Lausanne 80, 1202 Genève | Z6: Commerce and administration | AA6: Transformation et rénovation de bureaux au 6ème étage. | AB6: Detail card
A7: DRINGEND 6.pdf | B7: 1 | C7: =IF(L7="","C",IF(L7>=Lists!$I$2,"A",IF(L7>=Lists!$I$3,"B","C"))) -> B | D7: Architect / planner | E7: RIS + Partenaires Architectes SA | F7: Mr Antoine Ris | G7: 022 707 00 70 | H7: projets@ris-partenaires.ch | I7: Transformation et rénovation de bureaux | J7: 1202 Genève | K7: Permit granted | L7: 150000 | M7: =IF(G7="To be found",COUNTIF($E$2:$E$9999,E7),COUNTIF($G$2:$G$9999,G7)) -> 1 | N7: Reached – contact unavailable | O7: Call back | P7: 1 | Q7: 46297 | R7: Call back and ask for Mr Antoine Ris | S7: 46300 | T7: Reached RIS + Partenaires Architectes SA. Mr Antoine Ris was not available. Call back next week and ask directly for Mr Ris. The original Alixio / von Rundstedt project reference 3416925 is already completed. The objective of the next call is therefore to qualify RIS + Partenaires as a potential recurring architect / furniture prescriber for future office fit-out projects. Key points to qualify on the next call: - whether RIS directly specifies office furniture - whether Haworth is already known or used - current or upcoming office projects where furniture specification is still open - usual furniture brands / suppliers - possibility of a physical meeting with Manojlo Jelic | U7: 3416925 | V7: 46013 | W7: Avenue Rosemont 10, 1208 Genève | X7: http://www.ris-partenaires.ch | Y7: Rue de Lausanne 80, 1202 Genève | Z7: Commerce and administration | AA7: Transformation et rénovation de bureaux au 6ème étage. | AB7: Detail card
A8: DRINGEND 7.pdf | B8: 1 | C8: =IF(L8="","C",IF(L8>=Lists!$I$2,"A",IF(L8>=Lists!$I$3,"B","C"))) -> A | D8: Owner / client | E8: Ville de Morges | G8: 021 804 96 40 | H8: greffe@morges.ch | I8: Transformation d'une école de voile | J8: 1110 Morges | K8: Permit application filed | L8: 350000 | M8: =IF(G8="To be found",COUNTIF($E$2:$E$9999,E8),COUNTIF($G$2:$G$9999,G8)) -> 1 | N8: Voicemail / no answer | O8: Call back | P8: 1 | Q8: 46297 | R8: Call back | S8: 46300 | T8: Attempted to reach the relevant contact regarding project reference 3412698. Call went to voicemail / no answer. Retry next week. Project appears to still be potentially active and relevant for Haworth. The key objective on the next call is to determine: - current project stage - whether the furniture package is still open - who is responsible for furniture specification and purchasing - whether Club Nautique Morgien, Ville de Morges or Fehlmann Architectes is leading the furniture decision - whether a separate tender / procurement procedure is planned - timing for furniture selection - possibility of an on-site meeting with Manojlo Jelic Do not mark the opportunity as closed. | U8: 3412698 | V8: 45989 | W8: Place de l'Hôtel-de-Ville 1, code postale 272, 1110 Morges 1 | Y8: Place de la Navigation 1, 1110 Morges | Z8: Commerce and administration | AA8: Transformation du bâtiment ECA no 2670b avec création d'un bureau (école de voile) et d'un espace privé de réunion de 50 places avec possibilité de restauration pour les membres. Création d'une terrasse extérieure de 40 places. Isolation périphérique et revêtement de 27 cm, ouvertures en façade. Façade en lame de bois ajour ..> | AB8: Detail card
A9: DRINGEND 7.pdf | B9: 1 | C9: =IF(L9="","C",IF(L9>=Lists!$I$2,"A",IF(L9>=Lists!$I$3,"B","C"))) -> A | D9: Architect / planner | E9: Fehlmann Architectes SA | F9: Mr Serge Fehlmann | G9: 021 811 10 10 | H9: info@farch.ch | I9: Transformation d'une école de voile | J9: 1110 Morges | K9: Permit application filed | L9: 350000 | M9: =IF(G9="To be found",COUNTIF($E$2:$E$9999,E9),COUNTIF($G$2:$G$9999,G9)) -> 1 | N9: Reached reception – email requested | O9: Follow-up by email | P9: 1 | Q9: 46297 | R9: Send targeted email to info@farch.ch for the attention of Mr Serge Fehlmann | S9: 46301 | T9: Reached Fehlmann Architectes SA by phone on 02/10/2026. Reception explained that Mr Serge Fehlmann is unlikely to have time to handle this type of request by phone and specifically requested that the enquiry be sent by email to info@farch.ch. The email address and domain have been verified against Fehlmann Architectes SA's current official website: info@farch.ch Domain: farch.ch Do not send on Friday. Schedule the first email for Tuesday 06/10/2026 at approximately 09:00 Switzerland time. Project reference 3412698 still appears potentially relevant. Fehlmann Architectes SA is the architect / planner associated with the Club Nautique Morgien project at Place de la Navigation 1. Objective of the email: - establish contact with Mr Serge Fehlmann / the architect currently responsible for the project - determine the current stage of the project - determine whether the furniture package is still open - identify who specifies and selects the furniture - understand whether a procurement / tender procedure is planned - obtain a physical meeting with Haworth regional representative Manojlo Jelic if the furniture specification is still open Important: Do not treat the opportunity as closed. Do not send a generic Haworth catalogue email. The email should be short, project-specific and focused on the active Club Nautique Morgien project. | U9: 3412698 | V9: 45989 | W9: Place du Casino 2, Case postale 460, 1110 Morges 1 | X9: http://www.farch.ch | Y9: Place de la Navigation 1, 1110 Morges | Z9: Commerce and administration | AA9: Transformation du bâtiment ECA no 2670b avec création d'un bureau (école de voile) et d'un espace privé de réunion de 50 places avec possibilité de restauration pour les membres. Création d'une terrasse extérieure de 40 places. Isolation périphérique et revêtement de 27 cm, ouvertures en façade. Façade en lame de bois ajour ..> | AB9: Detail card
A10: DRINGEND 13.pdf | B10: 1 | C10: =IF(L10="","C",IF(L10>=Lists!$I$2,"A",IF(L10>=Lists!$I$3,"B","C"))) -> A | D10: Owner / client | E10: Societe Immobiliere de la Place de la Gare A SA | G10: To be found | I10: Aménagement d'un local d'exploitation - MBC | J10: 1110 Morges | K10: Permit application filed | L10: 300000 | M10: =IF(G10="To be found",COUNTIF($E$2:$E$9999,E10),COUNTIF($G$2:$G$9999,G10)) -> 1 | N10: IVR reached - unable to select menu option | O10: Call back | P10: 1 | Q10: 46297 | R10: Retry MBC / resolve Aircall DTMF issue | S10: 46300 | T10: Called MBC at 021 811 43 43 regarding project reference 3403243. Reached the automated telephone menu, but the Aircall keypad / DTMF input did not register, so it was not possible to reach the appropriate department. The project remains potentially active. A parallel contact attempt is being made through the project architect, Doutaz Architecture SA, under the separate Architect / planner row for project reference 3403243. | U10: 3403243 | V10: 45940 | W10: Grand-Rue 102, 1110 Morges | Y10: Rue Centrale 29, 1110 Morges | Z10: Industry and trade | AA10: Aménagement d'un local d'exploitation : création d'un vestiaire pour hommes, d'un vestiaire pour femmes, d'une salle d'allaitement/conférence, d'une salle de repos, de douches et de WC, d'une salle de pause/cafétéria, d'un dégagement et d'un local fumeur. | AB10: Detail card
A11: DRINGEND 13.pdf | B11: 1 | C11: =IF(L11="","C",IF(L11>=Lists!$I$2,"A",IF(L11>=Lists!$I$3,"B","C"))) -> A | D11: Architect / planner | E11: Doutaz Architecture SA | F11: Ms Anne Longchamp | G11: 026 564 20 20 | H11: info@doutaz-architecture.ch | I11: Aménagement d'un local d'exploitation - MBC | J11: 1110 Morges | K11: Permit application filed | L11: 300000 | M11: =IF(G11="To be found",COUNTIF($E$2:$E$9999,E11),COUNTIF($G$2:$G$9999,G11)) -> 1 | N11: Voicemail - office closed / unavailable on Fridays | O11: Call back | P11: 1 | Q11: 46297 | R11: Call back and ask for Anne Longchamp | S11: 46300 | T11: Called Doutaz Architecture SA on 02/10/2026 regarding project reference 3403243 / MBC premises at Rue Centrale 29, Morges. Reached the office answering machine. The message indicated that the office does not answer calls on Fridays. Call back on Monday 05/10/2026 and ask for Anne Longchamp. Anne Longchamp has been identified as the architect associated with the MBC project. Objective of next call: - confirm current project stage - determine whether the furniture package is still open - establish whether Doutaz Architecture is responsible for furniture specification - determine whether MBC or the architect selects the furniture suppliers - identify any procurement / tender process - determine expected timing for furniture selection - assess opportunity for a physical meeting with Manojlo Jelic Project remains potentially active. Do not close the opportunity. | U11: 3403243 | V11: 45940 | W11: Route de Riaz 97, 1630 Bulle | X11: http://www.doutaz-sa.ch | Y11: Rue Centrale 29, 1110 Morges | Z11: Industry and trade | AA11: Aménagement d'un local d'exploitation : création d'un vestiaire pour hommes, d'un vestiaire pour femmes, d'une salle d'allaitement/conférence, d'une salle de repos, de douches et de WC, d'une salle de pause/cafétéria, d'un dégagement et d'un local fumeur. | AB11: Detail card
A12: DRINGEND 15.pdf | B12: 1 | C12: =IF(L12="","C",IF(L12>=Lists!$I$2,"A",IF(L12>=Lists!$I$3,"B","C"))) -> C | D12: Owner / client | E12: HIAG Immobilier Schweiz AG | F12: Mr Patrick Japhet | G12: 022 304 10 30 | H12: info@hiag.com | I12: Changement d'affectation | J12: 1400 Yverdon-les-Bains | K12: Permit application filed | L12: 50000 | M12: =IF(G12="To be found",COUNTIF($E$2:$E$9999,E12),COUNTIF($G$2:$G$9999,G12)) -> 1 | N12: No answer | O12: Call back | P12: 1 | Q12: 46297 | R12: Call back and ask for Mr Patrick Japhet | S12: 46300 | T12: Attempted to reach Patrick Japhet regarding project reference 3404345 and the fit-out of a classroom at HIAG's Village 48 site in Yverdon-les-Bains. No answer. Call back on Monday 05/10/2026. The specific classroom project may already be completed or advanced, but HIAG remains a potentially valuable account as a major real estate owner / developer in French-speaking Switzerland. Objective of the next call: - confirm whether project 3404345 is completed - understand whether HIAG is involved in furniture selection for tenant fit-outs - determine whether furniture decisions are handled by HIAG, tenants or architects - identify the relevant person for interior fit-out / furniture in Western Switzerland - identify any current or upcoming projects where furniture specification is still open - assess potential for a physical meeting with Manojlo Jelic | U12: 3404345 | V12: 45947 | W12: Rue François-Bonivard 10, 1201 Genève | X12: http://www.hiag.com | Y12: Avenue de Grandson 48, 1400 Yverdon-les-Bains | Z12: Education and research | AA12: Changement d'affectation. Aménagement d'une salle de classe dans les locaux existants. | AB12: Detail card
A13: DRINGEND 15.pdf | B13: 1 | C13: =IF(L13="","C",IF(L13>=Lists!$I$2,"A",IF(L13>=Lists!$I$3,"B","C"))) -> C | D13: Architect / planner | E13: Studio 116 Architecture Architecte | F13: Mr Gaétan Mivelaz | G13: 077 403 52 58 | H13: archi@studio116.ch | I13: Changement d'affectation | J13: 1400 Yverdon-les-Bains | K13: Permit application filed | L13: 50000 | M13: =IF(G13="To be found",COUNTIF($E$2:$E$9999,E13),COUNTIF($G$2:$G$9999,G13)) -> 1 | O13: To call | P13: 0 | U13: 3404345 | V13: 45947 | W13: Chemin de la Fontaine 116, 1040 Echallens | Y13: Avenue de Grandson 48, 1400 Yverdon-les-Bains | Z13: Education and research | AA13: Changement d'affectation. Aménagement d'une salle de classe dans les locaux existants. | AB13: Detail card
A14: DRINGEND 19.pdf | B14: 1 | C14: =IF(L14="","C",IF(L14>=Lists!$I$2,"A",IF(L14>=Lists!$I$3,"B","C"))) -> A | D14: Owner / client | E14: Commune de Lausanne | G14: 021 315 49 49 | I14: Transformations intérieures de l'ancien Office | J14: 1003 Lausanne | K14: Permit application filed | L14: 900000 | M14: =IF(G14="To be found",COUNTIF($E$2:$E$9999,E14),COUNTIF($G$2:$G$9999,G14)) -> 1 | O14: To call | P14: 0 | U14: 3415421 | V14: 46003 | W14: Service des gérances, Place de Chaudron 9, 1003 Lausanne | Y14: Place de la Navigation 6, 1003 Lausanne | Z14: Commerce and administration | AA14: Transformations des locaux de l'ancien Office du tourisme au rez-de-chaussée pour la création d'un office bancaire avec installation d'un bancomat. Création de quatre guichets dont un fermé, une zone client, un sas de sécurité, un local de comptage, une cuisinette et un WC. | AB14: Detail card
A15: DRINGEND 19.pdf | B15: 1 | C15: =IF(L15="","C",IF(L15>=Lists!$I$2,"A",IF(L15>=Lists!$I$3,"B","C"))) -> A | D15: Architect / planner | E15: B2 Architecture + Protection Incendie Sàrl | F15: Ms Sophie Blanc-Hutmacher | G15: 079 774 39 47 | H15: info@bcarre.ch | I15: Transformations intérieures de l'ancien Office | J15: 1003 Lausanne | K15: Permit application filed | L15: 900000 | M15: =IF(G15="To be found",COUNTIF($E$2:$E$9999,E15),COUNTIF($G$2:$G$9999,G15)) -> 1 | O15: To call | P15: 0 | U15: 3415421 | V15: 46003 | W15: Rue des Salines 6, 1852 Roche VD | X15: http://www.bcarre.ch | Y15: Place de la Navigation 6, 1003 Lausanne | Z15: Commerce and administration | AA15: Transformations des locaux de l'ancien Office du tourisme au rez-de-chaussée pour la création d'un office bancaire avec installation d'un bancomat. Création de quatre guichets dont un fermé, une zone client, un sas de sécurité, un local de comptage, une cuisinette et un WC. | AB15: Detail card
A16: DRINGEND 20.pdf | B16: 1 | C16: =IF(L16="","C",IF(L16>=Lists!$I$2,"A",IF(L16>=Lists!$I$3,"B","C"))) -> A | D16: Architect / planner | E16: INEA Ingénierie Civile et Architecture | F16: Mr Steve Porscha | G16: 079 410 14 53 | I16: Surélévation, agrandissement et rénovation | J16: 1180 Rolle | K16: Permit application filed | L16: 790000 | M16: =IF(G16="To be found",COUNTIF($E$2:$E$9999,E16),COUNTIF($G$2:$G$9999,G16)) -> 1 | O16: To call | P16: 0 | U16: 3399157 | V16: 45919 | W16: Chemin de la Marjolatte 53, 1052 Le Mont-sur-Lausanne | Y16: Route de Lausanne 4, 1180 Rolle | Z16: Industry and trade | AA16: Surélévation, agrandissement et rénovation de 2 bâtiments industriels - création de surfaces de bureaux et d'espaces pour la recherche et développement d'équipements de sécurité. Agrandissement en structure métallique, façades en panneaux sandwich, toiture en panneaux sandwich, reconstruction et isolation des toiture basse. ..> | AB16: Detail card
A17: DRINGEND 24.pdf | B17: 1 | C17: =IF(L17="","C",IF(L17>=Lists!$I$2,"A",IF(L17>=Lists!$I$3,"B","C"))) -> A | D17: Owner / client | E17: Organisation météorologique mondiale - OMM | F17: Mr Anthony Duncker | G17: 022 730 81 11 | H17: wmo@wmo.int | I17: Transformations intérieures, raccordement bâtiment | J17: 1202 Genève | K17: Permit granted | L17: 500000 | M17: =IF(G17="To be found",COUNTIF($E$2:$E$9999,E17),COUNTIF($G$2:$G$9999,G17)) -> 1 | O17: To call | P17: 0 | U17: 3237651 | V17: 45939 | W17: World Meteorological Organization - WMO, Avenue de la Paix 7bis, Case postale, 1211 Genève 1 | X17: http://www.wmo.int | Y17: Avenue de la Paix 7bis, 1202 Genève | Z17: Commerce and administration | AA17: Transformations intérieures, aménagements extérieurs, raccordement du bâtiment au Genilac. Nouvelle prolongation de l'autorisation jusqu'au 19.12.2026 | AB17: Detail card
A18: DRINGEND 24.pdf | B18: 1 | C18: =IF(L18="","C",IF(L18>=Lists!$I$2,"A",IF(L18>=Lists!$I$3,"B","C"))) -> A | D18: Architect / planner | E18: Groupe H Architecture et Ingénierie SA | F18: Mr Nikola Radovanovic | G18: 022 782 05 40 | H18: architectes-ch@groupe-h.com | I18: Transformations intérieures, raccordement bâtiment | J18: 1202 Genève | K18: Permit granted | L18: 500000 | M18: =IF(G18="To be found",COUNTIF($E$2:$E$9999,E18),COUNTIF($G$2:$G$9999,G18)) -> 1 | O18: To call | P18: 0 | U18: 3237651 | V18: 45939 | W18: Chemin du Grand-Puits 42, 1217 Meyrin | X18: http://www.groupe-h.com | Y18: Avenue de la Paix 7bis, 1202 Genève | Z18: Commerce and administration | AA18: Transformations intérieures, aménagements extérieurs, raccordement du bâtiment au Genilac. Nouvelle prolongation de l'autorisation jusqu'au 19.12.2026 | AB18: Detail card
A19: DRINGEND 26.pdf | B19: 1 | C19: =IF(L19="","C",IF(L19>=Lists!$I$2,"A",IF(L19>=Lists!$I$3,"B","C"))) -> A | D19: Owner / client | E19: TESK Immo Sàrl | G19: To be found | I19: Transformation et agrandissement d'un dépôt | J19: 2852 Courtételle | K19: Permit application filed | L19: 300000 | M19: =IF(G19="To be found",COUNTIF($E$2:$E$9999,E19),COUNTIF($G$2:$G$9999,G19)) -> 1 | O19: To call | P19: 0 | U19: 3415587 | V19: 46002 | W19: Rue de la Rauracie 2, 2842 Rossemaison | Y19: Rue du Vieux-Moulin 53, 2852 Courtételle | Z19: Commerce and administration | AA19: Description du projet: Transformation et agrandissement du bâtiment No 53 pour bureaux, salle de conférence et exposition, pose de panneaux solaires, toiture et remplacement du chauffage à mazout par 2 PACS en façade sud, percement de 5 fenêtres au sud et 2 fenêtres au nord et construction d'un pavillon pour espace présenta ..> | AB19: Detail card
A20: DRINGEND 26.pdf | B20: 1 | C20: =IF(L20="","C",IF(L20>=Lists!$I$2,"A",IF(L20>=Lists!$I$3,"B","C"))) -> A | D20: Architect / planner | E20: AHD Architecture | G20: 077 985 29 64 | H20: info@ahdarchitecture.ch | I20: Transformation et agrandissement d'un dépôt | J20: 2852 Courtételle | K20: Permit application filed | L20: 300000 | M20: =IF(G20="To be found",COUNTIF($E$2:$E$9999,E20),COUNTIF($G$2:$G$9999,G20)) -> 1 | O20: To call | P20: 0 | U20: 3415587 | V20: 46002 | W20: Rue Emile-Boéchat 42, 2800 Delémont | Y20: Rue du Vieux-Moulin 53, 2852 Courtételle | Z20: Commerce and administration | AA20: Description du projet: Transformation et agrandissement du bâtiment No 53 pour bureaux, salle de conférence et exposition, pose de panneaux solaires, toiture et remplacement du chauffage à mazout par 2 PACS en façade sud, percement de 5 fenêtres au sud et 2 fenêtres au nord et construction d'un pavillon pour espace présenta ..> | AB20: Detail card
A21: DRINGEND 28.pdf | B21: 1 | C21: =IF(L21="","C",IF(L21>=Lists!$I$2,"A",IF(L21>=Lists!$I$3,"B","C"))) -> A | D21: Owner / client | E21: Top Store Braun Sàrl | G21: 079 450 52 78 | H21: info@top-stores.ch | I21: Construction bâtiment de bureaux, espace stockage | J21: 2803 Bourrignon | K21: Permit application filed | L21: 580000 | M21: =IF(G21="To be found",COUNTIF($E$2:$E$9999,E21),COUNTIF($G$2:$G$9999,G21)) -> 1 | O21: To call | P21: 0 | U21: 3401566 | V21: 45932 | W21: Droit Mont 1, 2803 Bourrignon | X21: http://www.top-stores.ch | Y21: Route Principale, 2803 Bourrignon | Z21: Commerce and administration | AA21: Description de l'ouvrage: Construction d'un bâtiment qui abritera des bureaux, un espace de stockage et un garage pour une voiture. Dimensions: Longueur 17,60m, largeur 8,80m, hauteur 4,98m, hauteur totale 6,63m. Genre de construction: Matériaux façades: enduit intérieur, brique TC, lame d'air, isolation, brique ciment, end ..> | AB21: Detail card
A22: DRINGEND 28.pdf | B22: 1 | C22: =IF(L22="","C",IF(L22>=Lists!$I$2,"A",IF(L22>=Lists!$I$3,"B","C"))) -> A | D22: General contractor | E22: 360° Comte Entreprise Générale SA | G22: 032 422 15 23 | H22: info@gcomte.ch | I22: Construction bâtiment de bureaux, espace stockage | J22: 2803 Bourrignon | K22: Permit application filed | L22: 580000 | M22: =IF(G22="To be found",COUNTIF($E$2:$E$9999,E22),COUNTIF($G$2:$G$9999,G22)) -> 1 | O22: To call | P22: 0 | U22: 3401566 | V22: 45932 | W22: Route de Moutier 93, 2800 Delémont | X22: http://www.360-comtesa.ch | Y22: Route Principale, 2803 Bourrignon | Z22: Commerce and administration | AA22: Description de l'ouvrage: Construction d'un bâtiment qui abritera des bureaux, un espace de stockage et un garage pour une voiture. Dimensions: Longueur 17,60m, largeur 8,80m, hauteur 4,98m, hauteur totale 6,63m. Genre de construction: Matériaux façades: enduit intérieur, brique TC, lame d'air, isolation, brique ciment, end ..> | AB22: Detail card
A23: DRINGEND 29.pdf | B23: 1 | C23: =IF(L23="","C",IF(L23>=Lists!$I$2,"A",IF(L23>=Lists!$I$3,"B","C"))) -> A | D23: Owner / client | E23: Braumann AG | F23: Mr Jörg Braumann | G23: 026 673 21 74 | H23: info@braumann.ch | I23: Rénovation d'un ancien bâtiment industriel | J23: 1786 Sugiez | K23: Permit granted | L23: 920000 | M23: =IF(G23="To be found",COUNTIF($E$2:$E$9999,E23),COUNTIF($G$2:$G$9999,G23)) -> 1 | O23: To call | P23: 0 | U23: 3330462 | V23: 45735 | W23: Route de l'Industrie 8, 1786 Sugiez | X23: http://www.braumann.ch | Y23: Chemin du Chablais 46, 1786 Sugiez | Z23: Industry and trade | AA23: Rénovation d'un ancien bâtiment industriel, ancienne halle transformé en espace de bureaux. Il s'agit essentiellement de travaux intérieurs de charpente, menuiserie intérieure, gipserie, électricité, chauffage sanitaire, revêtement intérieurs. | AB23: Detail card
A24: DRINGEND 29.pdf | B24: 1 | C24: =IF(L24="","C",IF(L24>=Lists!$I$2,"A",IF(L24>=Lists!$I$3,"B","C"))) -> A | D24: Architect / planner | E24: Atelier Pulver Architectes SA | G24: 026 673 03 63 | H24: info@aparchitectes.ch | I24: Rénovation d'un ancien bâtiment industriel | J24: 1786 Sugiez | K24: Permit granted | L24: 920000 | M24: =IF(G24="To be found",COUNTIF($E$2:$E$9999,E24),COUNTIF($G$2:$G$9999,G24)) -> 1 | O24: To call | P24: 0 | U24: 3330462 | V24: 45735 | W24: Route Principale 70, Case postale 9, 1786 Sugiez | X24: http://www.atelierpulver.ch | Y24: Chemin du Chablais 46, 1786 Sugiez | Z24: Industry and trade | AA24: Rénovation d'un ancien bâtiment industriel, ancienne halle transformé en espace de bureaux. Il s'agit essentiellement de travaux intérieurs de charpente, menuiserie intérieure, gipserie, électricité, chauffage sanitaire, revêtement intérieurs. | AB24: Detail card
A25: DRINGEND 32 .pdf | B25: 1 | C25: =IF(L25="","C",IF(L25>=Lists!$I$2,"A",IF(L25>=Lists!$I$3,"B","C"))) -> A | D25: Owner / client | E25: Sébastien Louis, Aline Raymonde et Anne Cécile Gampert | G25: 022 732 15 94 | I25: Changement d'affectation du logement en théâtre | J25: 1223 Cologny | K25: Permit granted | L25: 500000 | M25: =IF(G25="To be found",COUNTIF($E$2:$E$9999,E25),COUNTIF($G$2:$G$9999,G25)) -> 2 | O25: To call | P25: 0 | U25: 3358808 | V25: 45845 | W25: c/o atelier balan semadeni SNC, Avenue Blanc 51, 1202 Genève | Y25: Chemin de Ruth 16, 1223 Cologny | Z25: Culture and leisure | AA25: Rénovation du toit et des fenêtres, transformation intérieure et changement d'affectation du logement en théâtre | AB25: Detail card
A26: DRINGEND 32 .pdf | B26: 1 | C26: =IF(L26="","C",IF(L26>=Lists!$I$2,"A",IF(L26>=Lists!$I$3,"B","C"))) -> A | D26: Architect / planner | E26: Atelier Balan Semadeni SNC | F26: Ms Stefana Alexandra Balan Semadeni | G26: 022 732 15 94 | H26: info@balansemadeni.ch | I26: Changement d'affectation du logement en théâtre | J26: 1223 Cologny | K26: Permit granted | L26: 500000 | M26: =IF(G26="To be found",COUNTIF($E$2:$E$9999,E26),COUNTIF($G$2:$G$9999,G26)) -> 2 | O26: To call | P26: 0 | U26: 3358808 | V26: 45845 | W26: Avenue Blanc 51, 1202 Genève | X26: http://www.balansemadeni.ch | Y26: Chemin de Ruth 16, 1223 Cologny | Z26: Culture and leisure | AA26: Rénovation du toit et des fenêtres, transformation intérieure et changement d'affectation du logement en théâtre | AB26: Detail card
A27: DRINGEND 32.pdf | B27: 1 | C27: =IF(L27="","C",IF(L27>=Lists!$I$2,"A",IF(L27>=Lists!$I$3,"B","C"))) -> A | D27: Owner / client | E27: Etat de Genève-Département des Finances-Office des bâtiments | G27: 022 546 62 15 | H27: infodcti@etat.ge.ch | I27: Cycle d'orientation du Foron (101317000054) | J27: 1226 Thônex | K27: Permit granted | L27: 12000000 | M27: =IF(G27="To be found",COUNTIF($E$2:$E$9999,E27),COUNTIF($G$2:$G$9999,G27)) -> 2 | O27: To call | P27: 0 | U27: 3235065 | V27: 45251 | W27: Services des constructions et transformations, Boulevard de Saint-Georges 16/18, Case postale 32, 1211 Genève 8 | X27: http://www.ge.ch | Y27: Chemin du Foron 43, 1226 Thônex | Z27: Education and research | AA27: Cycle d'orientation du Foron - extension du bâtiment par surélévation et aménagement de 12 classes de cours - façade bois , toit plat en parti végétalisé - modification du stationnement - abattage et/ou élagage d'arbres hors forêt (RCVA) | AB27: Detail card | AC27: Same project as e_DRINGEND 83.pdf (p.2)
A28: DRINGEND 32.pdf | B28: 1 | C28: =IF(L28="","C",IF(L28>=Lists!$I$2,"A",IF(L28>=Lists!$I$3,"B","C"))) -> A | D28: Owner / client | E28: Etat de Genève, Département du territoire (DT) | G28: 022 546 62 00 | H28: ocbasac-marchespublics@etat.ge.ch | I28: Cycle d'orientation du Foron (101317000054) | J28: 1226 Thônex | K28: Permit granted | L28: 12000000 | M28: =IF(G28="To be found",COUNTIF($E$2:$E$9999,E28),COUNTIF($G$2:$G$9999,G28)) -> 5 | O28: To call | P28: 0 | U28: 3235065 | V28: 45251 | W28: Office cantonal des bâtiments (OCBA), Route des Jeunes 1A, Case postale 32, 1211 Genève 8 | X28: http://www.ge.ch | Y28: Chemin du Foron 43, 1226 Thônex | Z28: Education and research | AA28: Cycle d'orientation du Foron - extension du bâtiment par surélévation et aménagement de 12 classes de cours - façade bois , toit plat en parti végétalisé - modification du stationnement - abattage et/ou élagage d'arbres hors forêt (RCVA) | AB28: Detail card | AC28: Same project as e_DRINGEND 83.pdf (p.2)
A29: DRINGEND 32.pdf | B29: 1 | C29: =IF(L29="","C",IF(L29>=Lists!$I$2,"A",IF(L29>=Lists!$I$3,"B","C"))) -> A | D29: Owner / client | E29: Dep. des Infrastructures (DI) - Office cantonal des bâtiments - Direction des Rénovations et Transformations | G29: 022 546 53 90 | I29: Cycle d'orientation du Foron (101317000054) | J29: 1226 Thônex | K29: Permit granted | L29: 12000000 | M29: =IF(G29="To be found",COUNTIF($E$2:$E$9999,E29),COUNTIF($G$2:$G$9999,G29)) -> 2 | O29: To call | P29: 0 | U29: 3235065 | V29: 45251 | Y29: Chemin du Foron 43, 1226 Thônex | Z29: Education and research | AA29: Cycle d'orientation du Foron - extension du bâtiment par surélévation et aménagement de 12 classes de cours - façade bois , toit plat en parti végétalisé - modification du stationnement - abattage et/ou élagage d'arbres hors forêt (RCVA) | AB29: Summary table | AC29: Same project as e_DRINGEND 83.pdf (p.2)
A30: DRINGEND 32.pdf | B30: 1 | C30: =IF(L30="","C",IF(L30>=Lists!$I$2,"A",IF(L30>=Lists!$I$3,"B","C"))) -> A | D30: Architect / planner | E30: A-ARCHITECTES Sàrl | G30: 022 797 50 50 | I30: Cycle d'orientation du Foron (101317000054) | J30: 1226 Thônex | K30: Permit granted | L30: 12000000 | M30: =IF(G30="To be found",COUNTIF($E$2:$E$9999,E30),COUNTIF($G$2:$G$9999,G30)) -> 2 | O30: To call | P30: 0 | U30: 3235065 | V30: 45251 | Y30: Chemin du Foron 43, 1226 Thônex | Z30: Education and research | AA30: Cycle d'orientation du Foron - extension du bâtiment par surélévation et aménagement de 12 classes de cours - façade bois , toit plat en parti végétalisé - modification du stationnement - abattage et/ou élagage d'arbres hors forêt (RCVA) | AB30: Summary table | AC30: Same project as e_DRINGEND 83.pdf (p.2)
A31: DRINGEND 43.pdf | B31: 1 | C31: =IF(L31="","C",IF(L31>=Lists!$I$2,"A",IF(L31>=Lists!$I$3,"B","C"))) -> C | D31: Owner / client | E31: NAEF Surville SA | G31: 022 839 39 39 | I31: Aménagement intérieur de bureaux au 10ème étage | J31: 1213 Petit-Lancy | K31: Permit granted | L31: 50000 | M31: =IF(G31="To be found",COUNTIF($E$2:$E$9999,E31),COUNTIF($G$2:$G$9999,G31)) -> 3 | O31: To call | P31: 0 | U31: 3385673 | V31: 45854 | W31: Esplanade de Surville 2, 1213 Petit-Lancy | X31: http://www.naef.ch | Y31: Esplanade de Surville 2, 1213 Petit-Lancy | Z31: Commerce and administration | AA31: Aménagement intérieur de bureaux au 10ème étage | AB31: Detail card
A32: DRINGEND 43.pdf | B32: 1 | C32: =IF(L32="","C",IF(L32>=Lists!$I$2,"A",IF(L32>=Lists!$I$3,"B","C"))) -> C | D32: Architect / planner | E32: Alios SA | F32: Mr José Castro | G32: 022 839 37 78 | H32: info@alios-sa.ch | I32: Aménagement intérieur de bureaux au 10ème étage | J32: 1213 Petit-Lancy | K32: Permit granted | L32: 50000 | M32: =IF(G32="To be found",COUNTIF($E$2:$E$9999,E32),COUNTIF($G$2:$G$9999,G32)) -> 2 | O32: To call | P32: 0 | U32: 3385673 | V32: 45854 | W32: Avenue Eugène-Pittard 16, Case postale 6195, 1211 Genève 6 | X32: http://www.alios-sa.ch | Y32: Esplanade de Surville 2, 1213 Petit-Lancy | Z32: Commerce and administration | AA32: Aménagement intérieur de bureaux au 10ème étage | AB32: Detail card
A33: DRINGEND 44.pdf | B33: 1 | C33: =IF(L33="","C",IF(L33>=Lists!$I$2,"A",IF(L33>=Lists!$I$3,"B","C"))) -> B | D33: Owner / client | E33: Etat de Genève - Département des Infrastructures (DI) | F33: Mr Sandro Simioni | G33: 022 546 62 00 | H33: ocbasac-marchespublics@etat.ge.ch | I33: Construction d'une classe provisoire | J33: 1226 Thônex | K33: Permit granted | L33: 200000 | M33: =IF(G33="To be found",COUNTIF($E$2:$E$9999,E33),COUNTIF($G$2:$G$9999,G33)) -> 5 | O33: To call | P33: 0 | U33: 3385717 | V33: 45854 | W33: Office Cantonal des bâtiments (OCBA), Route des Jeunes 1a, Case postale 32, 1211 Genève 8 | X33: http://www.ge.ch | Y33: Chemin du Foron 43, 1226 Thônex | Z33: Education and research | AA33: Construction d'une classe provisoire (durée 15 mois) dans le cadre de la surélévation du cycle d'orientation du Foron | AB33: Detail card
A34: DRINGEND 44.pdf | B34: 1 | C34: =IF(L34="","C",IF(L34>=Lists!$I$2,"A",IF(L34>=Lists!$I$3,"B","C"))) -> B | D34: Architect / planner | E34: Glauco Lombardi Architectes Associés SA | F34: Mr Quentin Poncet | G34: 022 827 62 00 | H34: contact@glaucolombardi.ch | I34: Construction d'une classe provisoire | J34: 1226 Thônex | K34: Permit granted | L34: 200000 | M34: =IF(G34="To be found",COUNTIF($E$2:$E$9999,E34),COUNTIF($G$2:$G$9999,G34)) -> 1 | O34: To call | P34: 0 | U34: 3385717 | V34: 45854 | W34: Chemin de la Gravière 6, 1227 Les Acacias | X34: http://www.glaucolombardi.ch | Y34: Chemin du Foron 43, 1226 Thônex | Z34: Education and research | AA34: Construction d'une classe provisoire (durée 15 mois) dans le cadre de la surélévation du cycle d'orientation du Foron | AB34: Detail card
A35: DRINGEND 45.pdf | B35: 1 | C35: =IF(L35="","C",IF(L35>=Lists!$I$2,"A",IF(L35>=Lists!$I$3,"B","C"))) -> B | D35: Owner / client | E35: Hospice général, institution genevoise d'action sociale | F35: Ms Ersilia Salvi | G35: 022 420 52 00 | H35: contact@hospicegeneral.ch | I35: Aménagement de bureaux au 2ème et 5ème étage | J35: 1227 Carouge GE | K35: Permit granted | L35: 120000 | M35: =IF(G35="To be found",COUNTIF($E$2:$E$9999,E35),COUNTIF($G$2:$G$9999,G35)) -> 2 | O35: To call | P35: 0 | U35: 3385686 | V35: 45854 | W35: Cours de Rive 12, Case postale 3360, 1211 Genève 3 | X35: http://www.hospicegeneral.ch | Y35: Route des Acacias 54, 54bis, 1227 Carouge GE | Z35: Commerce and administration | AA35: Aménagement de bureaux au 2ème et 5ème étage | AB35: Detail card
A36: DRINGEND 45.pdf | B36: 1 | C36: =IF(L36="","C",IF(L36>=Lists!$I$2,"A",IF(L36>=Lists!$I$3,"B","C"))) -> B | D36: Architect / planner | E36: BKST Architectes SA | F36: Mr Bakir Mustajbegovic | G36: 022 575 61 20 | H36: info@bkst-architectes.ch | I36: Aménagement de bureaux au 2ème et 5ème étage | J36: 1227 Carouge GE | K36: Permit granted | L36: 120000 | M36: =IF(G36="To be found",COUNTIF($E$2:$E$9999,E36),COUNTIF($G$2:$G$9999,G36)) -> 1 | O36: To call | P36: 0 | U36: 3385686 | V36: 45854 | W36: Route des Acacias 43, 1227 Carouge GE | X36: http://www.bkst-architectes.ch | Y36: Route des Acacias 54, 54bis, 1227 Carouge GE | Z36: Commerce and administration | AA36: Aménagement de bureaux au 2ème et 5ème étage | AB36: Detail card
A37: DRINGEND 46.pdf | B37: 1 | C37: =IF(L37="","C",IF(L37>=Lists!$I$2,"A",IF(L37>=Lists!$I$3,"B","C"))) -> C | D37: Owner / client | E37: Hôpitaux Universitaires de Genève (HUG) | F37: Mr Jean-Charles Raetz | G37: 022 372 33 11 | I37: Aménagement de locaux au rez | J37: 1202 Genève | K37: Permit granted | L37: 80000 | M37: =IF(G37="To be found",COUNTIF($E$2:$E$9999,E37),COUNTIF($G$2:$G$9999,G37)) -> 1 | O37: To call | P37: 0 | U37: 3386117 | V37: 45855 | W37: Rue Gabrielle-Perret-Gentil 4, Case postale, 1211 Genève 14 | X37: http://www.hug-ge.ch | Y37: Chemin des Mines 9, 1202 Genève | Z37: Education and research | AA37: Aménagement de locaux au rez - accès plateforme PMR | AB37: Detail card
A38: DRINGEND 47.pdf | B38: 1 | C38: =IF(L38="","C",IF(L38>=Lists!$I$2,"A",IF(L38>=Lists!$I$3,"B","C"))) -> C | D38: Owner / client | E38: PSP Management AG | F38: Ms Aurélie Berg | G38: 044 625 57 57 | H38: zuerich@psp.info | I38: Division et aménagement d'un surface | J38: 1205 Genève | K38: Permit granted | L38: 50000 | M38: =IF(G38="To be found",COUNTIF($E$2:$E$9999,E38),COUNTIF($G$2:$G$9999,G38)) -> 1 | O38: To call | P38: 0 | U38: 3385940 | V38: 45855 | W38: Seestrasse 353, Postfach, 8038 Zürich | X38: http://www.psp.info | Y38: Rue des Bains 35, 1205 Genève | Z38: Commerce and administration | AA38: Division d'une surface et aménagement d'un surface au gré du preneur au 7ème étage | AB38: Detail card
A39: DRINGEND 47.pdf | B39: 1 | C39: =IF(L39="","C",IF(L39>=Lists!$I$2,"A",IF(L39>=Lists!$I$3,"B","C"))) -> C | D39: Architect / planner | E39: Giorgio Bello et Aydan Yurdakul | F39: Mr Giorgio Bello | G39: 022 738 09 33 | H39: atelier.g.a@bluewin.ch | I39: Division et aménagement d'un surface | J39: 1205 Genève | K39: Permit granted | L39: 50000 | M39: =IF(G39="To be found",COUNTIF($E$2:$E$9999,E39),COUNTIF($G$2:$G$9999,G39)) -> 1 | O39: To call | P39: 0 | U39: 3385940 | V39: 45855 | W39: Bureau d'architecte, Rue du Môle 42bis, 1201 Genève | X39: http://www.belloyurdakul.ch | Y39: Rue des Bains 35, 1205 Genève | Z39: Commerce and administration | AA39: Division d'une surface et aménagement d'un surface au gré du preneur au 7ème étage | AB39: Detail card
A40: DRINGEND 48.pdf | B40: 1 | C40: =IF(L40="","C",IF(L40>=Lists!$I$2,"A",IF(L40>=Lists!$I$3,"B","C"))) -> C | D40: Owner / client | E40: Labcorp Central Laboratory Services Sàrl | F40: Mr Stefano Fratianni | G40: 058 822 70 00 | H40: patricia.tirvaudey@labcorp.com | I40: Aménagement d'une unité de stockage | J40: 1217 Meyrin | K40: Permit granted | L40: 50000 | M40: =IF(G40="To be found",COUNTIF($E$2:$E$9999,E40),COUNTIF($G$2:$G$9999,G40)) -> 1 | O40: To call | P40: 0 | U40: 3385893 | V40: 45855 | W40: Rue Moïse-Marcinhes 7, 1217 Meyrin | X40: http://www.labcorp.com | Y40: Rue Emma-Kammacher 5b, 1217 Meyrin | Z40: Industry and trade | AA40: Aménagement d'une unité de stockage d'échantillons au 1er étage - raccordement sur installation de climatisation existante | AB40: Detail card
...

Sheet Projects
A1: PDF file | B1: Page | C1: Infopro project ref. | D1: Project | E1: Site location | F1: Site address | G1: Plot | H1: Stage | I1: Application published | J1: Permit granted | K1: Works value (CHF) | L1: Category | M1: Use | N1: Subcategories | O1: Description | P1: Infopro research date | Q1: Owner / client | R1: Architect / planner | S1: Contacts | T1: Contacts reached | U1: Interested / meetings / quotes | V1: Duplicate
A2: DRINGEND 4.pdf | B2: 1 | C2: 3417573 | D2: Aménagement d'un espace de coworking | E2: 1213 Petit-Lancy | F2: Route de Chancy 59, 1213 Petit-Lancy | G2: Parc. 611, 4950 | H2: Permit granted | J2: 46029 | K2: 50000 | L2: Commerce and administration | M2: Not relevant | N2: Offices (standard specification) – interior conversion | O2: Aménagement d'un espace de coworking au 3ème étage. | P2: 46029 | Q2: YNEO SA | R2: Marques | S2: =COUNTIFS(Calls!$A$2:$A$9999,$A2,Calls!$B$2:$B$9999,$B2) -> 2 | T2: =COUNTIFS(Calls!$A$2:$A$9999,$A2,Calls!$B$2:$B$9999,$B2,Calls!$N$2:$N$9999,"Reached*") -> 1 | U2: =COUNTIFS(Calls!$A$2:$A$9999,$A2,Calls!$B$2:$B$9999,$B2,Calls!$O$2:$O$9999,"Interested")+COUNTIFS(Calls!$A$2:$A$9999,$A2,Calls!$B$2:$B$9999,$B2,Calls!$O$2:$O$9999,"Meeting booked")+COUNTIFS(Calls!$A$2:$A$9999,$A2,Calls!$B$2:$B$9999,$B2,Calls!$O$2:$O$9999,"Quote requested") -> 0
A3: DRINGEND 5.pdf | B3: 1 | C3: 3416972 | D3: Aménagement de bureau | E3: 1206 Genève | F3: Route de Florissant 13, 1206 Genève | G3: Parc. 2361 | H3: Permit granted | J3: 46014 | K3: 40000 | L3: Commerce and administration | M3: Not relevant | N3: Offices (high specification) – interior conversion | O3: Aménagement de bureau au 7ème étage. | P3: 46014 | Q3: Yara Clean Ammonia Switzerland SA | R3: TJCA SA | S3: =COUNTIFS(Calls!$A$2:$A$9999,$A3,Calls!$B$2:$B$9999,$B3) -> 2 | T3: =COUNTIFS(Calls!$A$2:$A$9999,$A3,Calls!$B$2:$B$9999,$B3,Calls!$N$2:$N$9999,"Reached*") -> 1 | U3: =COUNTIFS(Calls!$A$2:$A$9999,$A3,Calls!$B$2:$B$9999,$B3,Calls!$O$2:$O$9999,"Interested")+COUNTIFS(Calls!$A$2:$A$9999,$A3,Calls!$B$2:$B$9999,$B3,Calls!$O$2:$O$9999,"Meeting booked")+COUNTIFS(Calls!$A$2:$A$9999,$A3,Calls!$B$2:$B$9999,$B3,Calls!$O$2:$O$9999,"Quote requested") -> 0
A4: DRINGEND 6.pdf | B4: 1 | C4: 3416925 | D4: Transformation et rénovation de bureaux | E4: 1202 Genève | F4: Rue de Lausanne 80, 1202 Genève | G4: Parc. 3737 | H4: Permit granted | J4: 46013 | K4: 150000 | L4: Commerce and administration | M4: Not relevant | N4: Offices (high specification) – interior conversion | O4: Transformation et rénovation de bureaux au 6ème étage. | P4: 46013 | Q4: von Rundstedt & Partner Suisse SA, succursale de Genève | R4: RIS + Partenaires Architectes SA | S4: =COUNTIFS(Calls!$A$2:$A$9999,$A4,Calls!$B$2:$B$9999,$B4) -> 2 | T4: =COUNTIFS(Calls!$A$2:$A$9999,$A4,Calls!$B$2:$B$9999,$B4,Calls!$N$2:$N$9999,"Reached*") -> 2 | U4: =COUNTIFS(Calls!$A$2:$A$9999,$A4,Calls!$B$2:$B$9999,$B4,Calls!$O$2:$O$9999,"Interested")+COUNTIFS(Calls!$A$2:$A$9999,$A4,Calls!$B$2:$B$9999,$B4,Calls!$O$2:$O$9999,"Meeting booked")+COUNTIFS(Calls!$A$2:$A$9999,$A4,Calls!$B$2:$B$9999,$B4,Calls!$O$2:$O$9999,"Quote requested") -> 0
A5: DRINGEND 7.pdf | B5: 1 | C5: 3412698 | D5: Transformation d'une école de voile | E5: 1110 Morges | F5: Place de la Navigation 1, 1110 Morges | G5: Parc. 115, 1405 | H5: Permit application filed | I5: 45989 | K5: 350000 | L5: Commerce and administration | N5: Offices (high specification) – interior conversion Restaurants – interior conversion Restaurants – extension | O5: Transformation du bâtiment ECA no 2670b avec création d'un bureau (école de voile) et d'un espace privé de réunion de 50 places avec possibilité de restauration pour les membres. Création d'une terrasse extérieure de 40 places. Isolation périphérique et revêtement de 27 cm, ouvertures en façade. Façade en lame de bois ajour ..> | P5: 45992 | Q5: Ville de Morges | R5: Fehlmann Architectes SA | S5: =COUNTIFS(Calls!$A$2:$A$9999,$A5,Calls!$B$2:$B$9999,$B5) -> 2 | T5: =COUNTIFS(Calls!$A$2:$A$9999,$A5,Calls!$B$2:$B$9999,$B5,Calls!$N$2:$N$9999,"Reached*") -> 1 | U5: =COUNTIFS(Calls!$A$2:$A$9999,$A5,Calls!$B$2:$B$9999,$B5,Calls!$O$2:$O$9999,"Interested")+COUNTIFS(Calls!$A$2:$A$9999,$A5,Calls!$B$2:$B$9999,$B5,Calls!$O$2:$O$9999,"Meeting booked")+COUNTIFS(Calls!$A$2:$A$9999,$A5,Calls!$B$2:$B$9999,$B5,Calls!$O$2:$O$9999,"Quote requested") -> 0
A6: DRINGEND 13.pdf | B6: 1 | C6: 3403243 | D6: Aménagement d'un local d'exploitation - MBC | E6: 1110 Morges | F6: Rue Centrale 29, 1110 Morges | G6: Parc. 4169 | H6: Permit application filed | I6: 45940 | K6: 300000 | L6: Industry and trade | N6: Operational and commercial buildings – interior conversion | O6: Aménagement d'un local d'exploitation : création d'un vestiaire pour hommes, d'un vestiaire pour femmes, d'une salle d'allaitement/conférence, d'une salle de repos, de douches et de WC, d'une salle de pause/cafétéria, d'un dégagement et d'un local fumeur. | P6: 45944 | Q6: Societe Immobiliere de la Place de la Gare A SA | R6: Doutaz Architecture SA | S6: =COUNTIFS(Calls!$A$2:$A$9999,$A6,Calls!$B$2:$B$9999,$B6) -> 2 | T6: =COUNTIFS(Calls!$A$2:$A$9999,$A6,Calls!$B$2:$B$9999,$B6,Calls!$N$2:$N$9999,"Reached*") -> 0 | U6: =COUNTIFS(Calls!$A$2:$A$9999,$A6,Calls!$B$2:$B$9999,$B6,Calls!$O$2:$O$9999,"Interested")+COUNTIFS(Calls!$A$2:$A$9999,$A6,Calls!$B$2:$B$9999,$B6,Calls!$O$2:$O$9999,"Meeting booked")+COUNTIFS(Calls!$A$2:$A$9999,$A6,Calls!$B$2:$B$9999,$B6,Calls!$O$2:$O$9999,"Quote requested") -> 0
A7: DRINGEND 15.pdf | B7: 1 | C7: 3404345 | D7: Changement d'affectation | E7: 1400 Yverdon-les-Bains | F7: Avenue de Grandson 48, 1400 Yverdon-les-Bains | G7: Parc. 1254 | H7: Permit application filed | I7: 45947 | K7: 50000 | L7: Education and research | M7: Not relevant | N7: Primary and secondary schools – interior conversion | O7: Changement d'affectation. Aménagement d'une salle de classe dans les locaux existants. | P7: 45947 | Q7: HIAG Immobilier Schweiz AG | R7: Studio 116 Architecture Architecte | S7: =COUNTIFS(Calls!$A$2:$A$9999,$A7,Calls!$B$2:$B$9999,$B7) -> 2 | T7: =COUNTIFS(Calls!$A$2:$A$9999,$A7,Calls!$B$2:$B$9999,$B7,Calls!$N$2:$N$9999,"Reached*") -> 0 | U7: =COUNTIFS(Calls!$A$2:$A$9999,$A7,Calls!$B$2:$B$9999,$B7,Calls!$O$2:$O$9999,"Interested")+COUNTIFS(Calls!$A$2:$A$9999,$A7,Calls!$B$2:$B$9999,$B7,Calls!$O$2:$O$9999,"Meeting booked")+COUNTIFS(Calls!$A$2:$A$9999,$A7,Calls!$B$2:$B$9999,$B7,Calls!$O$2:$O$9999,"Quote requested") -> 0
A8: DRINGEND 19.pdf | B8: 1 | C8: 3415421 | D8: Transformations intérieures de l'ancien Office | E8: 1003 Lausanne | F8: Place de la Navigation 6, 1003 Lausanne | G8: Parc. 5419 | H8: Permit application filed | I8: 46003 | K8: 900000 | L8: Commerce and administration | N8: Offices (standard specification) – interior conversion Offices (standard specification) – exterior conversion Offices (standard specification) – extension | O8: Transformations des locaux de l'ancien Office du tourisme au rez-de-chaussée pour la création d'un office bancaire avec installation d'un bancomat. Création de quatre guichets dont un fermé, une zone client, un sas de sécurité, un local de comptage, une cuisinette et un WC. | P8: 46007 | Q8: Commune de Lausanne | R8: B2 Architecture + Protection Incendie Sàrl | S8: =COUNTIFS(Calls!$A$2:$A$9999,$A8,Calls!$B$2:$B$9999,$B8) -> 2 | T8: =COUNTIFS(Calls!$A$2:$A$9999,$A8,Calls!$B$2:$B$9999,$B8,Calls!$N$2:$N$9999,"Reached*") -> 0 | U8: =COUNTIFS(Calls!$A$2:$A$9999,$A8,Calls!$B$2:$B$9999,$B8,Calls!$O$2:$O$9999,"Interested")+COUNTIFS(Calls!$A$2:$A$9999,$A8,Calls!$B$2:$B$9999,$B8,Calls!$O$2:$O$9999,"Meeting booked")+COUNTIFS(Calls!$A$2:$A$9999,$A8,Calls!$B$2:$B$9999,$B8,Calls!$O$2:$O$9999,"Quote requested") -> 0
A9: DRINGEND 20.pdf | B9: 1 | C9: 3399157 | D9: Surélévation, agrandissement et rénovation | E9: 1180 Rolle | F9: Route de Lausanne 4, 1180 Rolle | G9: Parc. 608 | H9: Permit application filed | I9: 45919 | K9: 790000 | L9: Industry and trade | N9: Industrial halls – extension Industrial halls – interior conversion Industrial halls – exterior conversion Offices (high specification) – interior conversion | O9: Surélévation, agrandissement et rénovation de 2 bâtiments industriels - création de surfaces de bureaux et d'espaces pour la recherche et développement d'équipements de sécurité. Agrandissement en structure métallique, façades en panneaux sandwich, toiture en panneaux sandwich, reconstruction et isolation des toiture basse. ..> | P9: 45925 | R9: INEA Ingénierie Civile et Architecture | S9: =COUNTIFS(Calls!$A$2:$A$9999,$A9,Calls!$B$2:$B$9999,$B9) -> 1 | T9: =COUNTIFS(Calls!$A$2:$A$9999,$A9,Calls!$B$2:$B$9999,$B9,Calls!$N$2:$N$9999,"Reached*") -> 0 | U9: =COUNTIFS(Calls!$A$2:$A$9999,$A9,Calls!$B$2:$B$9999,$B9,Calls!$O$2:$O$9999,"Interested")+COUNTIFS(Calls!$A$2:$A$9999,$A9,Calls!$B$2:$B$9999,$B9,Calls!$O$2:$O$9999,"Meeting booked")+COUNTIFS(Calls!$A$2:$A$9999,$A9,Calls!$B$2:$B$9999,$B9,Calls!$O$2:$O$9999,"Quote requested") -> 0
A10: DRINGEND 24.pdf | B10: 1 | C10: 3237651 | D10: Transformations intérieures, raccordement bâtiment | E10: 1202 Genève | F10: Avenue de la Paix 7bis, 1202 Genève | G10: Parc. 5039 | H10: Permit granted | I10: 45135 | J10: 45939 | K10: 500000 | L10: Commerce and administration | N10: Administrative buildings and data centres – interior conversion Administrative buildings and data centres – exterior conversion Administrative buildings and data centres – extension | O10: Transformations intérieures, aménagements extérieurs, raccordement du bâtiment au Genilac. Nouvelle prolongation de l'autorisation jusqu'au 19.12.2026 | P10: 45939 | Q10: Organisation météorologique mondiale - OMM | R10: Groupe H Architecture et Ingénierie SA | S10: =COUNTIFS(Calls!$A$2:$A$9999,$A10,Calls!$B$2:$B$9999,$B10) -> 2 | T10: =COUNTIFS(Calls!$A$2:$A$9999,$A10,Calls!$B$2:$B$9999,$B10,Calls!$N$2:$N$9999,"Reached*") -> 0 | U10: =COUNTIFS(Calls!$A$2:$A$9999,$A10,Calls!$B$2:$B$9999,$B10,Calls!$O$2:$O$9999,"Interested")+COUNTIFS(Calls!$A$2:$A$9999,$A10,Calls!$B$2:$B$9999,$B10,Calls!$O$2:$O$9999,"Meeting booked")+COUNTIFS(Calls!$A$2:$A$9999,$A10,Calls!$B$2:$B$9999,$B10,Calls!$O$2:$O$9999,"Quote requested") -> 0
A11: DRINGEND 26.pdf | B11: 1 | C11: 3415587 | D11: Transformation et agrandissement d'un dépôt | E11: 2852 Courtételle | F11: Rue du Vieux-Moulin 53, 2852 Courtételle | G11: Parc. 1857 | H11: Permit application filed | I11: 46002 | K11: 300000 | L11: Commerce and administration | M11: Own use | N11: Shops – interior conversion Shops – extension Offices (high specification) – interior conversion Offices (high specification) – extension | O11: Description du projet: Transformation et agrandissement du bâtiment No 53 pour bureaux, salle de conférence et exposition, pose de panneaux solaires, toiture et remplacement du chauffage à mazout par 2 PACS en façade sud, percement de 5 fenêtres au sud et 2 fenêtres au nord et construction d'un pavillon pour espace présenta ..> | P11: 46008 | Q11: TESK Immo Sàrl | R11: AHD Architecture | S11: =COUNTIFS(Calls!$A$2:$A$9999,$A11,Calls!$B$2:$B$9999,$B11) -> 2 | T11: =COUNTIFS(Calls!$A$2:$A$9999,$A11,Calls!$B$2:$B$9999,$B11,Calls!$N$2:$N$9999,"Reached*") -> 0 | U11: =COUNTIFS(Calls!$A$2:$A$9999,$A11,Calls!$B$2:$B$9999,$B11,Calls!$O$2:$O$9999,"Interested")+COUNTIFS(Calls!$A$2:$A$9999,$A11,Calls!$B$2:$B$9999,$B11,Calls!$O$2:$O$9999,"Meeting booked")+COUNTIFS(Calls!$A$2:$A$9999,$A11,Calls!$B$2:$B$9999,$B11,Calls!$O$2:$O$9999,"Quote requested") -> 0
